<?xml version="1.0" ?>
<robot name="RocketForURDF">

<material name="silver">
  <color rgba="0.700 0.700 0.700 1.000"/>
</material>

<link name="Torso_1">
  <inertial>
    <origin xyz="0 0 0" rpy="0 0 0"/>
    <mass value="2.158125"/>
    <inertia ixx="0.023244" iyy="0.031679" izz="0.012812" ixy="0.0" iyz="0.000141" ixz="0.000024"/>
  </inertial>
  <visual>
    <origin xyz="0.0 0.0 0.0" rpy="0 0 0"/>
    <geometry>
      <mesh filename="package://meshes/Torso_1.stl" scale="0.001 0.001 0.001"/>
    </geometry>
    <material name="silver"/>
  </visual>
  <collision>
    <origin xyz="0.0 0.0 0.0" rpy="0 0 0"/>
    <geometry>
      <mesh filename="package://meshes/Torso_1.stl" scale="0.001 0.001 0.001"/>
    </geometry>
  </collision>
</link>

<link name="Hip_L_1">
  <inertial>
    <origin xyz="0 0 0" rpy="0 0 0"/>
    <mass value="1.017088"/>
    <inertia ixx="0.000592" iyy="0.001156" izz="0.001114" ixy="0" iyz="0" ixz="0"/>
  </inertial>
  <visual>
    <origin xyz="0.066 0 -0.02" rpy="0 0 0"/>
    <geometry>
      <mesh filename="package://meshes/Hip_L_1.stl" scale="0.001 0.001 0.001"/>
    </geometry>
    <material name="silver"/>
  </visual>
  <collision>
    <origin xyz="0.066 0 -0.02" rpy="0 0 0"/>
    <geometry>
      <mesh filename="package://meshes/Hip_L_1.stl" scale="0.001 0.001 0.001"/>
    </geometry>
  </collision>
</link>

<link name="Hip_R_1">
  <inertial>
    <origin xyz="0 0 0" rpy="0 0 0"/>
    <mass value="1.017208"/>
    <inertia ixx="0.000592" iyy="0.001156" izz="0.001114" ixy="0" iyz="0" ixz="0"/>
  </inertial>
  <visual>
    <origin xyz="-0.066 0 -0.02" rpy="0 0 0"/>
    <geometry>
      <mesh filename="package://meshes/Hip_R_1.stl" scale="0.001 0.001 0.001"/>
    </geometry>
    <material name="silver"/>
  </visual>
  <collision>
    <origin xyz="-0.066 0 -0.02" rpy="0 0 0"/>
    <geometry>
      <mesh filename="package://meshes/Hip_R_1.stl" scale="0.001 0.001 0.001"/>
    </geometry>
  </collision>
</link>

<link name="Thigh_L_1">
  <inertial>
    <origin xyz="0 0 0" rpy="0 0 0"/>
    <mass value="1.225024"/>
    <inertia ixx="0.002582" iyy="0.001994" izz="0.001962" ixy="-0.000302" iyz="0.000789" ixz="0.000307"/>
  </inertial>
  <visual>
    <origin xyz="0.115 0 -0.07" rpy="0 0 0"/>
    <geometry>
      <mesh filename="package://meshes/Thigh_L_1.stl" scale="0.001 0.001 0.001"/>
    </geometry>
    <material name="silver"/>
  </visual>
  <collision>
    <origin xyz="0.115 0 -0.07" rpy="0 0 0"/>
    <geometry>
      <mesh filename="package://meshes/Thigh_L_1.stl" scale="0.001 0.001 0.001"/>
    </geometry>
  </collision>
</link>

<link name="Thigh_R_1">
  <inertial>
    <origin xyz="0 0 0" rpy="0 0 0"/>
    <mass value="1.225024"/>
    <inertia ixx="0.002582" iyy="0.001994" izz="0.001962" ixy="0.000302" iyz="0.000789" ixz="-0.000307"/>
  </inertial>
  <visual>
    <origin xyz="-0.115 0 -0.07" rpy="0 0 0"/>
    <geometry>
      <mesh filename="package://meshes/Thigh_R_1.stl" scale="0.001 0.001 0.001"/>
    </geometry>
    <material name="silver"/>
  </visual>
  <collision>
    <origin xyz="-0.115 0 -0.07" rpy="0 0 0"/>
    <geometry>
      <mesh filename="package://meshes/Thigh_R_1.stl" scale="0.001 0.001 0.001"/>
    </geometry>
  </collision>
</link>

<link name="Calf_L_1">
  <inertial>
    <origin xyz="0 0 0" rpy="0 0 0"/>
    <mass value="0.106437"/>
    <inertia ixx="0.000403" iyy="0.00026" izz="0.000291" ixy="0.000009" iyz="-0.000175" ixz="0.000008"/>
  </inertial>
  <visual>
    <origin xyz="0.101 -0.099 0.029" rpy="0 0 0"/>
    <geometry>
      <mesh filename="package://meshes/Calf_L_1.stl" scale="0.001 0.001 0.001"/>
    </geometry>
    <material name="silver"/>
  </visual>
  <collision>
    <origin xyz="0.101 -0.099 0.029" rpy="0 0 0"/>
    <geometry>
      <mesh filename="package://meshes/Calf_L_1.stl" scale="0.001 0.001 0.001"/>
    </geometry>
  </collision>
</link>

<link name="Calf_R_1">
  <inertial>
    <origin xyz="0 0 0" rpy="0 0 0"/>
    <mass value="0.106436"/>
    <inertia ixx="0.000403" iyy="0.00026" izz="0.000291" ixy="-0.000009" iyz="-0.000175" ixz="-0.000008"/>
  </inertial>
  <visual>
    <origin xyz="-0.101 -0.099 0.029" rpy="0 0 0"/>
    <geometry>
      <mesh filename="package://meshes/Calf_R_1.stl" scale="0.001 0.001 0.001"/>
    </geometry>
    <material name="silver"/>
  </visual>
  <collision>
    <origin xyz="-0.101 -0.099 0.029" rpy="0 0 0"/>
    <geometry>
      <mesh filename="package://meshes/Calf_R_1.stl" scale="0.001 0.001 0.001"/>
    </geometry>
  </collision>
</link>

<link name="Toe_L_1">
  <inertial>
    <origin xyz="0 0 0" rpy="0 0 0"/>
    <mass value="0.015585"/>
    <inertia ixx="0.000002" iyy="0.000005" izz="0.000005" ixy="0" iyz="0" ixz="0"/>
  </inertial>
  <visual>
    <origin xyz="0.138 -0.011 0.104" rpy="0 0 0"/>
    <geometry>
      <mesh filename="package://meshes/Toe_L_1.stl" scale="0.001 0.001 0.001"/>
    </geometry>
    <material name="silver"/>
  </visual>
  <collision>
    <origin xyz="0.138 -0.011 0.104" rpy="0 0 0"/>
    <geometry>
      <mesh filename="package://meshes/Toe_L_1.stl" scale="0.001 0.001 0.001"/>
    </geometry>
  </collision>
</link>

<link name="Toe_R_1">
  <inertial>
    <origin xyz="0 0 0" rpy="0 0 0"/>
    <mass value="0.015585"/>
    <inertia ixx="0.000002" iyy="0.000005" izz="0.000005" ixy="0" iyz="0" ixz="0"/>
  </inertial>
  <visual>
    <origin xyz="-0.138 -0.011 0.104" rpy="0 0 0"/>
    <geometry>
      <mesh filename="package://meshes/Toe_R_1.stl" scale="0.001 0.001 0.001"/>
    </geometry>
    <material name="silver"/>
  </visual>
  <collision>
    <origin xyz="-0.138 -0.011 0.104" rpy="0 0 0"/>
    <geometry>
      <mesh filename="package://meshes/Toe_R_1.stl" scale="0.001 0.001 0.001"/>
    </geometry>
  </collision>
</link>

<joint name="Revolute1" type="revolute">
  <origin xyz="-0.066 0 0.02" rpy="0 0 0"/>
  <parent link="Torso_1"/>
  <child link="Hip_L_1"/>
  <axis xyz="0 0 -1"/>
  <limit upper="0.0349" lower="-0.0349" effort="1000" velocity="100"/>
</joint>

<joint name="Revolute2" type="revolute">
  <origin xyz="0.066 0 0.02" rpy="0 0 0"/>
  <parent link="Torso_1"/>
  <child link="Hip_R_1"/>
  <axis xyz="0 0 1"/>
  <limit upper="0.0349" lower="-0.0349" effort="1000" velocity="100"/>
</joint>

<joint name="Revolute3" type="revolute">
  <origin xyz="-0.049 0 0.05" rpy="0 0 0"/>
  <parent link="Hip_L_1"/>
  <child link="Thigh_L_1"/>
  <axis xyz="1.0 0.0 0.0"/>
  <limit upper="0.1745" lower="-0.3490" effort="1000" velocity="100"/>
</joint>

<joint name="Revolute4" type="revolute">
  <origin xyz="0.049 0 0.05" rpy="0 0 0"/>
  <parent link="Hip_R_1"/>
  <child link="Thigh_R_1"/>
  <axis xyz="1.0 0.0 0.0"/>
  <limit upper="0.1745" lower="-0.3490" effort="1000" velocity="100"/>
</joint>

<joint name="Revolute5" type="revolute">
  <origin xyz="0.014 0.099 -0.099" rpy="0 0 0"/>
  <parent link="Thigh_L_1"/>
  <child link="Calf_L_1"/>
  <axis xyz="-1.0 0 0"/>
  <limit upper="0.2618" lower="-0.3490" effort="1000" velocity="100"/>
</joint>

<joint name="Revolute6" type="revolute">
  <origin xyz="-0.014 0.099 -0.099" rpy="0 0 0"/>
  <parent link="Thigh_R_1"/>
  <child link="Calf_R_1"/>
  <axis xyz="-1.0 0 0"/>
  <limit upper="0.2618" lower="-0.3490" effort="1000" velocity="100"/>
</joint>

<joint name="Rigid7" type="fixed">
  <origin xyz="-0.037 -0.087 -0.075" rpy="0 0 0"/>
  <parent link="Calf_L_1"/>
  <child link="Toe_L_1"/>
</joint>

<joint name="Rigid8" type="fixed">
  <origin xyz="0.037 -0.087 -0.075" rpy="0 0 0"/>
  <parent link="Calf_R_1"/>
  <child link="Toe_R_1"/>
</joint>

</robot>
